<?xml version="1.0" ?>
<!-- =================================================================================== -->
<!-- |    This document was autogenerated by xacro from Robot.xacro                    | -->
<!-- |    EDITING THIS FILE BY HAND IS NOT RECOMMENDED                                 | -->
<!-- =================================================================================== -->
<!-- Name your robot here -->
<robot name="Assem" xmlns:xacro="http://wiki.ros.org/xacro">
  <link name="dummy_link">
  </link>
  <joint name="dummy_link" type="fixed">
    <parent link="dummy_link"/>
    <child link="base_link"/>
  </joint>
  <gazebo>
    <plugin filename="libgazebo_ros_diff_drive.so" name="differential_drive_controller">
      <legacyMode>false</legacyMode>
      <alwaysOn>true</alwaysOn>
      <updateRate>20</updateRate>
      <leftJoint>left_f</leftJoint>
      <rightJoint>right_f</rightJoint>
      <wheelSeparation>0.5334</wheelSeparation>
      <wheelDiameter>0.1032</wheelDiameter>
      <torque>5.0</torque>
      <commandTopic>cmd_vel</commandTopic>
      <odometryTopic>odom</odometryTopic>
      <odometryFrame>odom</odometryFrame>
      <robotBaseFrame>base_link</robotBaseFrame>
    </plugin>
  </gazebo>
  <link name="base_link">
    <inertial>
      <origin rpy="0 0 0" xyz="-0.0016914 0.0127 -0.01121"/>
      <mass value="4"/>
      <inertia ixx="0.83564" ixy="2.6064E-18" ixz="0.0007444" iyy="1.0742" iyz="7.9758E-19" izz="0.23955"/>
    </inertial>
    <visual>
      <origin rpy="0 0 0" xyz="0 0 0"/>
      <geometry>
        <mesh filename="package://project1/meshes/base_link.STL"/>
      </geometry>
      <material name="">
        <color rgba="0.79216 0.81961 0.93333 1"/>
      </material>
    </visual>
    <collision>
      <origin rpy="0 0 0" xyz="0 0 0"/>
      <geometry>
        <mesh filename="package://project1/meshes/base_link.STL"/>
      </geometry>
    </collision>
  </link>
  <link name="left_f_Link">
    <inertial>
      <origin rpy="0 0 0" xyz="0.0382293903121097 -1.73472347597681E-18 0"/>
      <mass value="1.57907589778326"/>
      <inertia ixx="0.00880766574640623" ixy="8.97187520246957E-20" ixz="-2.39573040315552E-20" iyy="0.00400202473857838" iyz="3.16915422768057E-05" izz="0.00632680350392821"/>
    </inertial>
    <visual>
      <origin rpy="0 0 0" xyz="0 0 0"/>
      <geometry>
        <mesh filename="package://project1/meshes/left_f_Link.STL"/>
      </geometry>
      <material name="">
        <color rgba="0.792156862745098 0.819607843137255 0.933333333333333 1"/>
      </material>
    </visual>
    <collision>
      <origin rpy="0 0 0" xyz="0 0 0"/>
      <geometry>
        <mesh filename="package://project1/meshes/left_f_Link.STL"/>
      </geometry>
    </collision>
  </link>
  <joint name="left_f" type="continuous">
    <origin rpy="1.4934 0 0" xyz="0.2667 -0.254 0.0127"/>
    <parent link="base_link"/>
    <child link="left_f_Link"/>
    <axis xyz="1 0 0"/>
  </joint>
  <link name="left_b_Link">
    <inertial>
      <origin rpy="0 0 0" xyz="0.0382293903121097 -3.46944695195361E-18 0"/>
      <mass value="1.57907589778326"/>
      <inertia ixx="0.00880766574640623" ixy="1.16769056939019E-19" ixz="-2.89368343198518E-19" iyy="0.00400202473857838" iyz="3.16915422768003E-05" izz="0.00632680350392821"/>
    </inertial>
    <visual>
      <origin rpy="0 0 0" xyz="0 0 0"/>
      <geometry>
        <mesh filename="package://project1/meshes/left_b_Link.STL"/>
      </geometry>
      <material name="">
        <color rgba="0.792156862745098 0.819607843137255 0.933333333333333 1"/>
      </material>
    </visual>
    <collision>
      <origin rpy="0 0 0" xyz="0 0 0"/>
      <geometry>
        <mesh filename="package://project1/meshes/left_b_Link.STL"/>
      </geometry>
    </collision>
  </link>
  <joint name="left_b" type="continuous">
    <origin rpy="1.5456 0 0" xyz="0.2667 0.254 0.0127"/>
    <parent link="base_link"/>
    <child link="left_b_Link"/>
    <axis xyz="1 0 0"/>
  </joint>
  <link name="right_f_Link">
    <inertial>
      <origin rpy="0 0 0" xyz="0.0382293903121098 1.73472347597681E-18 0"/>
      <mass value="1.57907589778326"/>
      <inertia ixx="0.00880766574640622" ixy="2.93945738314315E-21" ixz="2.09244409814948E-19" iyy="0.00400202473857838" iyz="3.16915422767972E-05" izz="0.00632680350392821"/>
    </inertial>
    <visual>
      <origin rpy="0 0 0" xyz="0 0 0"/>
      <geometry>
        <mesh filename="package://project1/meshes/right_f_Link.STL"/>
      </geometry>
      <material name="">
        <color rgba="0.792156862745098 0.819607843137255 0.933333333333333 1"/>
      </material>
    </visual>
    <collision>
      <origin rpy="0 0 0" xyz="0 0 0"/>
      <geometry>
        <mesh filename="package://project1/meshes/right_f_Link.STL"/>
      </geometry>
    </collision>
  </link>
  <joint name="right_f" type="continuous">
    <origin rpy="-1.48 0 -3.1416" xyz="-0.2667 -0.254 0.0127"/>
    <parent link="base_link"/>
    <child link="right_f_Link"/>
    <axis xyz="1 0 0"/>
  </joint>
  <link name="right_b_Link">
    <inertial>
      <origin rpy="0 0 0" xyz="0.0382293903121097 -5.20417042793042E-18 0"/>
      <mass value="1.57907589778326"/>
      <inertia ixx="0.00880766574640623" ixy="8.48274680339935E-20" ixz="-5.67037306013235E-20" iyy="0.00400202473857838" iyz="3.1691542276803E-05" izz="0.00632680350392821"/>
    </inertial>
    <visual>
      <origin rpy="0 0 0" xyz="0 0 0"/>
      <geometry>
        <mesh filename="package://project1/meshes/right_b_Link.STL"/>
      </geometry>
      <material name="">
        <color rgba="0.792156862745098 0.819607843137255 0.933333333333333 1"/>
      </material>
    </visual>
    <collision>
      <origin rpy="0 0 0" xyz="0 0 0"/>
      <geometry>
        <mesh filename="package://project1/meshes/right_b_Link.STL"/>
      </geometry>
    </collision>
  </link>
  <joint name="right_b" type="continuous">
    <origin rpy="-1.5708 0 3.1416" xyz="-0.2667 0.254 0.0127"/>
    <parent link="base_link"/>
    <child link="right_b_Link"/>
    <axis xyz="1 0 0"/>
  </joint>
  <link name="base_laser">
    <inertial>
      <origin rpy="0 0 0" xyz="-0.00029774 0.0066667 0.00013047"/>
      <mass value="0.15717"/>
      <inertia ixx="6.7885E-05" ixy="-1.3987E-07" ixz="-8.1554E-07" iyy="0.00013173" iyz="-9.0932E-08" izz="7.1972E-05"/>
    </inertial>
    <visual>
      <origin rpy="0 0 0" xyz="0 0 0"/>
      <geometry>
        <mesh filename="package://project1/meshes/ydlidar.dae"/>
      </geometry>
      <material name="">
        <color rgba="0.64706 0.61961 0.58824 1"/>
      </material>
    </visual>
    <collision>
      <origin rpy="0 0 0" xyz="0 0 0"/>
      <geometry>
        <mesh filename="package://project1/meshes/ydlidar.dae"/>
      </geometry>
    </collision>
  </link>
  <link name="laser_frame">
    <inertial>
      <origin rpy="0 0 0" xyz="-0.00036659 0.00064155 -0.00027052"/>
      <mass value="0.25482"/>
      <inertia ixx="8.9194E-05" ixy="1.8116E-07" ixz="3.6435E-08" iyy="0.00018279" iyz="2.423E-07" izz="0.00011103"/>
    </inertial>
    <!--visual>
      <origin
        xyz="0 0 0"
        rpy="0 0 0" />
      <geometry>
        <mesh
          filename="package://ydlidar_ros/meshes/ydlidar.dae" />
      </geometry>
      <material
        name="">
        <color
          rgba="0.64706 0.61961 0.58824 1" />
      </material>
    </visual-->
    <!--collision>
      <origin
        xyz="0 0 0"
        rpy="0 0 0" />
      <geometry>
        <mesh
          filename="package://ydlidar_ros/meshes/ydlidar.dae" />
      </geometry>
    </collision-->
  </link>
  <joint name="laser_joint" type="fixed">
    <origin rpy="0 0 0" xyz="0 0 0.03172"/>
    <parent link="base_laser"/>
    <child link="laser_frame"/>
    <axis xyz="0 0 0"/>
  </joint>
  <!-- Add your gazebo sensors here -->
  <gazebo reference="base_laser">
    <!-- <gravity>true</gravity> -->
    <!-- Gazebo has fixed set of Sensors types. Check them out here <> -->
    <sensor name="laser" type="ray">
      <!-- Add in your sensor characteristics -->
      <pose> 0 0 0 0 0 0 </pose>
      <visualise>true</visualise>
      <update_rate>40</update_rate>
      <!-- <always_on>true</always_on> -->
      <ray>
        <scan>
          <horizontal>
            <samples>720</samples>
            <resolution>1</resolution>
            <min_angle>-1.570796</min_angle>
            <max_angle>1.570796</max_angle>
          </horizontal>
        </scan>
        <range>
          <min>0.10</min>
          <max>30.0</max>
          <resolution>0.01</resolution>
        </range>
        <noise>
          <type>gaussian</type>
          <mean>0.0</mean>
          <stddev>0.01</stddev>
        </noise>
      </ray>
      <plugin filename="libgazebo_ros_laser.so" name="gazebo_ros_head_hokuyo_controller">
        <!-- Use topic name as /my_robot/scan -->
        <topicName>project1/scan</topicName>
        <frameName>laser_frame</frameName>
      </plugin>
    </sensor>
  </gazebo>
  <!-- Create a joint between your robot and sensor -->
  <joint name="joint_sensor_laser" type="fixed">
    <origin rpy="0 0 1.57" xyz="0.15 0.42 0.028"/>
    <parent link="base_link"/>
    <child link="base_laser"/>
  </joint>
</robot>

